<?xml version='1.0' encoding='utf-8'?>
<robot name="export_test">
  <mujoco>
    <compiler meshdir="../meshes/" balanceinertia="true" discardvisual="false" />
  </mujoco>
  <link name="base_link">
    <inertial>
      <origin xyz="0 0.00903 0.02859" rpy="0 0 0" />
      <mass value="4.0754" />
      <inertia ixx="0.00659" ixy="0" ixz="0" iyy="0.01444" iyz="0" izz="0.0197" />
    </inertial>
    <visual>
      <origin xyz="0 0 0" rpy="0 0 0" />
      <geometry>
      	  
          <mesh filename="../meshes/base_waist.obj" />
      </geometry>
      <material name="">
        <color rgba="0 0 0 1" />
      </material>
    </visual>
    <collision>
      <origin xyz="0 0 -0.05" rpy="0 0 0" />
      <geometry>
      	  <box size="0.10 0.08 0.05" />
          
      </geometry>
    </collision>
  </link>
  <link name="link_right_hip_yaw">
    <inertial>
      <origin xyz="0.0004598 -0.072941 0.0945646" rpy="0 0 0" />
      <mass value="0.51040" />
      <inertia ixx="0.0001" ixy="0" ixz="0" iyy="0.0010" iyz="0.00017" izz="0.000605" />
    </inertial>
    <visual>
      <origin xyz="0 0 0" rpy="0 0 0" />
      <geometry>
      
        <mesh filename="../meshes/link_right_hip_yaw.obj" />
      </geometry>
      <material name="">
        <color rgba="0.8980 0.917647 0.92941 1" />
      </material>
    </visual>
    <collision>
      <origin xyz="0 -0.12 0.10" rpy="0 0 0" />
      <geometry>
      <sphere radius="0.05" />
        
      </geometry>
    </collision>
  </link>
  <joint name="joint_right_hip_yaw" type="revolute">
    <origin xyz="-0.13999 0 0.0538" rpy="-3.14 0 0" />
    <parent link="base_link" />
    <child link="link_right_hip_yaw" />
    <axis xyz="0 0 1" />
    <limit lower="-0.6" upper="0.4" effort="112" velocity="9" />
    <dynamics damping="0" friction="0" />
  </joint>
  <link name="link_right_hip_roll">
    <inertial>
      <origin xyz="0.0019474 0 0.0931034" rpy="0 0 0" />
      <mass value="0.40532" />
      <inertia ixx="0.000848" ixy="0" ixz="0" iyy="0.000597" iyz="0" izz="0.00038" />
    </inertial>
    <visual>
      <origin xyz="0 0 0" rpy="0 0 0" />
      <geometry>
      
        <mesh filename="../meshes/link_right_hip_roll.obj" />
      </geometry>
      <material name="">
        <color rgba="0.89803 0.917647 0.929411 1" />
      </material>
    </visual>
    <collision>
      <origin xyz="0 0 0.1" rpy="0 0 0" />
      <geometry>
      <sphere radius="0.05" />
        
      </geometry>
    </collision>
  </link>
  <joint name="joint_right_hip_roll" type="revolute">
    <origin xyz="0.0005 -0.103 0.1108" rpy="-1.5708 0 0" />
    <parent link="link_right_hip_yaw" />
    <child link="link_right_hip_roll" />
    <axis xyz="0 0 1" />
    <limit lower="-0.15" upper="0.15" effort="216" velocity="6" />
    <dynamics damping="0" friction="0" />
  </joint>
  <link name="link_right_thigh">
    <inertial>
      <origin xyz="0 -0.1715747 0.02551" rpy="0 0 0" />
      <mass value="1.3865" />
      <inertia ixx="0.00889" ixy="-0.00099" ixz="0" iyy="0.001264" iyz="0" izz="0.00979" />
    </inertial>
    <visual>
      <origin xyz="0 0 0" rpy="0 0 0" />
      <geometry>
      	
          <mesh filename="../meshes/link_right_thigh.obj" />
      </geometry>
      <material name="">
        <color rgba="0.7921 0.8196 0.9333 1" />
      </material>
    </visual>
    <collision>
      <origin xyz="0 -0.2 0" rpy="1.57 0 0" />
      <geometry>
      	<cylinder radius="0.045" length="0.2" />
          
      </geometry>
    </collision>
  </link>
  <joint name="joint_right_hip_pitch" type="revolute">
    <origin xyz="-0.01099 0 0.1049" rpy="0 1.5707 0" />
    <parent link="link_right_hip_roll" />
    <child link="link_right_thigh" />
    <axis xyz="0 0 1" />
    <limit lower="-1.5" upper="0.3" effort="216" velocity="6" />
    <dynamics damping="0" friction="0" />
  </joint>
  <link name="link_right_shank">
    <inertial>
      <origin xyz="0.14691 0.011433 -0.000180" rpy="0 0 0" />
      <mass value="2.256" />
      <inertia ixx="0.00119" ixy="-0.00021" ixz="0" iyy="0.0109" iyz="0" izz="0.01175" />
    </inertial>
    <visual>
      <origin xyz="0 0 0" rpy="0 0 0" />
      <geometry>
      
        <mesh filename="../meshes/link_right_shank.obj" />
      </geometry>
      <material name="">
        <color rgba="1 1 1 1" />
      </material>
    </visual>
    <collision>
      <origin xyz="0.1 0 0" rpy="0 1.57 0" />
      <geometry>
      <cylinder radius="0.025" length="0.2" />
        
      </geometry>
    </collision>
  </link>
  <joint name="joint_right_knee_pitch" type="revolute">
    <origin xyz="0 -0.38520 0.0254" rpy="0 0 -1.5707" />
    <parent link="link_right_thigh" />
    <child link="link_right_shank" />
    <axis xyz="0 0 -1" />
    <limit lower="-2.2" upper="0" effort="216" velocity="6" />
    <dynamics damping="0" friction="0" />
  </joint>
  <link name="link_right_ankle_pitch">
    <inertial>
      <origin xyz="0 0 0" rpy="0 0 0" />
      <mass value="2.256" />
      <inertia ixx="0.00119" ixy="-0.00021" ixz="0" iyy="0.0109" iyz="0" izz="0.01175" />
    </inertial>
    <visual>
      <origin xyz="0 0 0" rpy="0 0 0" />
      <geometry>
        <mesh filename="../meshes/link_right_ankle_pitch.obj" />
      </geometry>
      <material name="">
        <color rgba="0.7764 0.75686 0.73725 1" />
      </material>
    </visual>
    
  </link>
  <joint name="joint_right_ankle_pitch" type="revolute">
    <origin xyz="0.355 0 0" rpy="0 0 4.71" />
    <parent link="link_right_shank" />
    <child link="link_right_ankle_pitch" />
    <axis xyz="0 0 1" />
    <limit lower="-0.6" upper="0.6" effort="112" velocity="9" />
    <dynamics damping="0" friction="0.1" />
  </joint>
  <link name="link_right_ankle_roll">
    <inertial>
      <origin xyz="0.000529 -0.060500 0.03277" rpy="0 0 0" />
      <mass value="1.294" />
      <inertia ixx="0.002826" ixy="0" ixz="0" iyy="0.00322" iyz="0" izz="0.000511" />
    </inertial>
    <visual>
      <origin xyz="0 0 0" rpy="0 0 0" />
      <geometry>
      
        <mesh filename="../meshes/link_right_ankle_roll.obj" />
      </geometry>
      <material name="">
        <color rgba="1 1 1 1" />
      </material>
    </visual>
    <collision>
      <origin xyz="0 0 0" rpy="0 0 0" />
      <geometry>
      
        <mesh filename="../meshes/link_right_ankle_roll.obj" />
      </geometry>
    </collision>
  </link>
  <joint name="joint_right_ankle_roll" type="revolute">
    <origin xyz="0 0 0" rpy="3.1416 -1.5708 0" />
    <parent link="link_right_ankle_pitch" />
    <child link="link_right_ankle_roll" />
    <axis xyz="0 0 1" />
    <limit lower="-0.52" upper="0.52" effort="112" velocity="9" />
    <dynamics damping="0" friction="0.1" />
  </joint>
  <link name="link_left_hip_yaw">
    <inertial>
      <origin xyz="0 0 0" rpy="0 0 0" />
      <mass value="1.294" />
      <inertia ixx="0.002826" ixy="0" ixz="0" iyy="0.00322" iyz="0" izz="0.000511" />
    </inertial>
    <visual>
      <origin xyz="0 0 0" rpy="0 0 0" />
      <geometry>
      	
        <mesh filename="../meshes/link_left_hip_yaw.obj" />
      </geometry>
      <material name="">
        <color rgba="1 1 1 1" />
      </material>
    </visual>
    <collision>
      <origin xyz="0 -0.12 0.1" rpy="0 0 0" />
      <geometry>
      	<sphere radius="0.05" />
        
      </geometry>
    </collision>
  </link>
  <joint name="joint_left_hip_yaw" type="revolute">
    <origin xyz="0.13999 0 0.0538" rpy="-3.14 0 0" />
    <parent link="base_link" />
    <child link="link_left_hip_yaw" />
    <axis xyz="0 0 -1" />
    <limit lower="-0.6" upper="0.4" effort="112" velocity="9" />
    <dynamics damping="0" friction="0" />
  </joint>
  <link name="link_left_hip_roll">
    <inertial>
      <origin xyz="-0.00194 0 0.093103" rpy="0 0 0" />
      <mass value="0.40532" />
      <inertia ixx="0.000848" ixy="0" ixz="0" iyy="0.00059" iyz="0" izz="0.000380" />
    </inertial>
    <visual>
      <origin xyz="0 0 0" rpy="0 0 0" />
      <geometry>
      
        <mesh filename="../meshes/link_left_hip_roll.obj" />
      </geometry>
      <material name="">
        <color rgba="1 1 1 1" />
      </material>
    </visual>
    <collision>
      <origin xyz="0 0 0.1" rpy="0 0 0" />
      <geometry>
      <sphere radius="0.05" />
        
      </geometry>
    </collision>
  </link>
  <joint name="joint_left_hip_roll" type="revolute">
    <origin xyz="-0.000499 -0.1029 0.11079" rpy="-1.5707963267949 0 0" />
    <parent link="link_left_hip_yaw" />
    <child link="link_left_hip_roll" />
    <axis xyz="0 0 -1" />
    <limit lower="-0.15" upper="0.15" effort="216" velocity="6" />
    <dynamics damping="0" friction="0" />
  </joint>
  <link name="link_left_thigh">
    <inertial>
      <origin xyz="0 -0.1722 -0.01457" rpy="0 0 0" />
      <mass value="1.3869" />
      <inertia ixx="0.0088" ixy="-0.0009" ixz="0" iyy="0.00126" iyz="0" izz="0.00979" />
    </inertial>
    <visual>
      <origin xyz="0 0 0" rpy="0 0 0" />
      <geometry>
      
        <mesh filename="../meshes/link_left_thigh.obj" />
      </geometry>
      <material name="">
        <color rgba="0.7921 0.8196 0.933 1" />
      </material>
    </visual>
    <collision>
      <origin xyz="0 -0.2 0" rpy="1.57 0 0" />
      <geometry>
      	<cylinder radius="0.045" length="0.2" />
        
      </geometry>
    </collision>
  </link>
  <joint name="joint_left_hip_pitch" type="revolute">
    <origin xyz="0 0 0.1049" rpy="0 1.5707 0" />
    <parent link="link_left_hip_roll" />
    <child link="link_left_thigh" />
    <axis xyz="0 0 1" />
    <limit lower="-1.5" upper="0.3" effort="216" velocity="6" />
    <dynamics damping="0" friction="0" />
  </joint>
  <link name="link_left_shank">
    <inertial>
      <origin xyz="0.0113 -0.14655 0.00020" rpy="0 0 0" />
      <mass value="2.252" />
      <inertia ixx="0.01091" ixy="0.0002" ixz="0" iyy="0.00119" iyz="0" izz="0.01175" />
    </inertial>
    <visual>
      <origin xyz="0 0 0" rpy="0 0 0" />
      <geometry>
      
        <mesh filename="../meshes/link_left_shank.obj" />
      </geometry>
      <material name="">
        <color rgba="0.79215 0.81960 0.9333 1" />
      </material>
    </visual>
    <collision>
      <origin xyz="0 -0.1 0" rpy="1.57 0 0" />
      <geometry>
      <cylinder radius="0.025" length="0.2" />
        
      </geometry>
    </collision>
  </link>
  <joint name="joint_left_knee_pitch" type="revolute">
    <origin xyz="0 -0.3852 -0.0144" rpy="0 0 0" />
    <parent link="link_left_thigh" />
    <child link="link_left_shank" />
    <axis xyz="0 0 -1" />
    <limit lower="-2.2" upper="0" effort="216" velocity="6" />
    <dynamics damping="0" friction="0" />
  </joint>
  <link name="link_left_ankle_pitch">
    <inertial>
      <origin xyz="0 0 0" rpy="0 0 0" />
      <mass value="1.294" />
      <inertia ixx="0.002826" ixy="0" ixz="0" iyy="0.00322" iyz="0" izz="0.000511" />
    </inertial>
    <visual>
      <origin xyz="0 0 0" rpy="0 0 0" />
      <geometry>
        <mesh filename="../meshes/link_left_ankle_pitch.obj" />
      </geometry>
      <material name="">
        <color rgba="0.792 0.8196 0.93333 1" />
      </material>
    </visual>
    
  </link>
  <joint name="joint_left_ankle_pitch" type="revolute">
    <origin xyz="0 -0.3549 0" rpy="0 0 3.14" />
    <parent link="link_left_shank" />
    <child link="link_left_ankle_pitch" />
    <axis xyz="0 0 1" />
    <limit lower="-0.6" upper="0.6" effort="112" velocity="9" />
    <dynamics damping="0" friction="0.1" />
  </joint>
  <link name="link_left_ankle_roll">
    <inertial>
      <origin xyz="-0.000530 -0.06046 0.032780" rpy="0 0 0" />
      <mass value="1.2953" />
      <inertia ixx="0.00282" ixy="0" ixz="0" iyy="0.00322" iyz="0" izz="0.00051" />
    </inertial>
    <visual>
      <origin xyz="0 0 0" rpy="0 0 0" />
      <geometry>
      
        <mesh filename="../meshes/link_left_ankle_roll.obj" />
      </geometry>
      <material name="">
        <color rgba="0.7921 0.8196 0.9333 1" />
      </material>
    </visual>
    <collision>
      <origin xyz="0 0 0" rpy="0 0 0" />
      <geometry>
      	
        <mesh filename="../meshes/link_left_ankle_roll.obj" />
      </geometry>
    </collision>
  </link>
  <joint name="joint_left_ankle_roll" type="revolute">
    <origin xyz="0 0 0" rpy="3.14 -1.57 0" />
    <parent link="link_left_ankle_pitch" />
    <child link="link_left_ankle_roll" />
    <axis xyz="0 0 1" />
    <limit lower="-0.52" upper="0.52" effort="112" velocity="9" />
    <dynamics damping="0" friction="0.1" />
  </joint>

</robot>